Workbook

Sheet 0_README
A1: DAY 28 — MONETIZATION MODEL
A2: AI Pricing · GTM · Evidence — AI-IN-ACTION Track 1
A4: QUY ƯỚC MÀU — CHỈ ĐIỀN VÀO Ô MÀU VÀNG
A5: Ô VÀNG, chữ xanh dương | B5: Ô bạn phải điền
A6: Ô XÁM, chữ đen | B6: Công thức tự tính — KHÔNG SỬA
A7: Chữ xanh lá | B7: Link sang tab khác
A8: Ô XÁM đậm nhạt | B8: Bảng tham chiếu, chỉ đọc
A10: THỨ TỰ LÀM — 6 TRẠM, 120 PHÚT
A11: Trạm 1 · 15' | B11: Ngân sách khách & định nghĩa Job → điền S1–S2 của tab 1_Cost_Job
A12: Trạm 2 · 20' | B12: Value Metric → tab 3_Value_Metric
A13: Trạm 3 · 30' | B13: Cost/Job, giá sàn & giá trần → tab 1_Cost_Job (S3–S8) rồi 2_Pricing
A14: Trạm 4 · 20' | B14: Kênh phân phối & Affordability Test → tab 4_Channel_Fit
A15: Trạm 5 · 15' | B15: Pain Moment & 90-Day Plan → tab 5_90Day_Plan
A16: Trạm 6 · 20' | B16: Evidence Pack & ráp One-Pager → tab 5_90Day_Plan + file .docx
A18: 3 QUY TẮC KHÔNG ĐƯỢC PHÁ
A19: 1. Chia cho số job HOÀN THÀNH, không phải số job đã thử.
A20: 2. HITL và Retry không được để 0 nếu không có lý do viết ra được.
A21: 3. Mọi con số giá API phải có NGÀY kiểm tra (xem tab 6_Benchmarks).
A23: Giá tham chiếu trong workbook này được chốt ngày 26/08/2026. Nhiều mức giá là KHUYẾN MẠI CÓ HẠN.
A24: Bạn PHẢI tự mở lại trang giá của nhà cung cấp và cập nhật — đây là một phần của bài tập.

Sheet 1_Cost_Job
A1: TAB 1 — COST/JOB CALCULATOR
A2: Trạm 1 (S1–S2) và Trạm 3 (S3–S8). Chỉ điền ô vàng.
A4: S1. ĐỊNH NGHĨA JOB
A5: 1 job của bạn là gì? | B5: 1 báo cáo Sprint/tháng AI-ready: đủ nguồn Jira/GitHub/AI ledger, coverage ≥80%, không lỗi nghiêm trọng; CTO review riêng. | D5: Phải là thứ KHÁCH coi là giá trị — không phải '1 request'
A6: Biến thể HITL: A hay B? | B6: A | D6: A = khách tự xử lý ca escalate · B = BẠN chịu (outcome/managed)
A8: S2. KHỐI LƯỢNG
A9: Số job THỬ / tháng | B9: 40 | C9: job
A10: Containment rate (AI tự làm xong) | B10: 0.75 | D10: Chưa đo → ước tính và ghi rõ
A11: → Số job HOÀN THÀNH / tháng | B11: =B9*B10 | C11: job | D11: MẪU SỐ của Cost/Job
A12: → Số job KHÔNG xong / tháng | B12: =B9-B11 | C12: job | D12: Số ca phải escalate
A14: S3. API — LLM
A15: Giá input ($ / 1M token) | B15: 1 | D15: Claude Haiku 4.5 — xem tab 6_Benchmarks
A16: Giá output ($ / 1M token) | B16: 5
A17: Giá cache WRITE ($ / 1M token) | B17: 1.25 | D17: Anthropic 5-phút = 1,25× input
A18: Giá cache READ ($ / 1M token) | B18: 0.1 | D18: ≈ 0,1× input (giảm 90%)
A19: Số lượt (turns) / job | B19: 4 | C19: lượt
A20: Token input CACHE ĐƯỢC / lượt | B20: 8000 | C20: token | D20: System prompt + KB + few-shot
A21: Token input FRESH / lượt | B21: 12000 | C21: token | D21: Câu hỏi khách + dữ liệu động
A22: Token output / lượt | B22: 2000 | C22: token
A23: → Cache write / job | B23: =B20*B17/1000000
A24: → Cache read / job | B24: =(B19-1)*B20*B18/1000000
A25: → Input fresh / job | B25: =B19*B21*B15/1000000
A26: → Output / job | B26: =B19*B22*B16/1000000
A27: → LLM / job — CÓ prompt caching | B27: =SUM(B23:B26)
A28: → LLM / job — KHÔNG cache | B28: =B19*(B20+B21)*B15/1000000+B26
A29: → % tiết kiệm nhờ caching | B29: =IF(B28=0,0,1-B27/B28) | D29: Đòn bẩy rẻ nhất bạn có
A30: Dùng Batch API? (1 = có, 0 = không) | B30: 0 | D30: Batch giảm 50% — chỉ khi job KHÔNG cần realtime
A31: → LLM / job sau Batch | B31: =B27*(1-B30*0.5)
A33: S4. API — SPEECH (để 0 nếu sản phẩm không có thoại)
A34: Giá STT ($ / phút) | B34: 0 | D34: Deepgram streaming list $0,0077/phút
A35: Số phút audio / job | B35: 0 | C35: phút
A36: Giá TTS ($ / 1M ký tự) | B36: 0 | D36: ElevenLabs Flash $50 · Google Standard $4
A37: Số ký tự TTS / job | B37: 0 | C37: ký tự | D37: ≈ 900 ký tự cho mỗi phút bot nói
A38: → Speech / job | B38: =B34*B35+B36*B37/1000000
A40: S5. INFRA
A41: Infra / job ($) | B41: 10 | D41: Vector DB, embedding, storage, logging
A42: Telephony ($ / phút) | B42: 0
A43: → Infra / job | B43: =B41+B42*B35
A45: S6. RETRY
A46: Tỷ lệ job phải chạy lại | B46: 0.08 | D46: ĐỪNG để 0%. Thực tế 5–10% là bình thường
...

Sheet 2_Pricing
A1: TAB 2 — PRICING SANITY CHECK
A2: Trạm 3. Cost/Job tự lấy từ tab 1. Bạn điền giá bán và các con số neo giá.
A4: GIÁ SÀN
A5: Cost/Job (từ tab 1_Cost_Job) | B5: ='1_Cost_Job'!B66 | C5: $/job
A6: Hệ số an toàn tối thiểu | B6: 3 | C6: × | D6: Giá bán ≥ 3 × Cost/Job
A7: → GIÁ SÀN | B7: =B5*B6 | C7: $/job
A9: GIÁ TRẦN — NEO THEO THỨ KHÁCH ĐANG CHI
A10: Giá trị khách tiết kiệm được / tháng ($) | B10: 1200 | D10: Neo theo giá trị
A11: Số job / tháng của 1 khách | B11: 3 | C11: job
A12: → Trần theo giá trị — mức 10% | B12: =IF(B11=0,0,B10*0.1/B11) | C12: $/job
A13: → Trần theo giá trị — mức 25% | B13: =IF(B11=0,0,B10*0.25/B11) | C13: $/job
A14: Lương / tháng của vị trí bị thay ($) | B14: 2000 | D14: Neo theo nhân công
A15: → Trần theo nhân công — mức 50% | B15: =IF(B11=0,0,B14*0.5/B11) | C15: $/job
A16: → Trần theo nhân công — mức 70% | B16: =IF(B11=0,0,B14*0.7/B11) | C16: $/job
A18: GIÁ BÁN CỦA BẠN
A19: ★ Giá bán đề xuất ($ / job) | B19: 60 | C19: $/job | D19: Tham chiếu: Intercom Fin $0,99 · Zendesk $1,50
A20: → Bội số so với Cost/Job | B20: =IF(B5=0,0,B19/B5)
A21: → GROSS MARGIN | B21: =IF(B19=0,0,(B19-B5)/B19)
A22: → Đèn: bội số ≥ 3? | B22: =IF(B20>=B6,"OK — ĐẠT","KHÔNG ĐẠT — quay lại tab 1")
A23: → Đèn: Gross Margin | B23: =IF(B21>=0.6,"OK — AN TOÀN (≥60%)",IF(B21>=0.5,"CẢNH BÁO (50–60%)","NGUY HIỂM (<50%)"))
A24: → Đèn: GM có cao bất thường? | B24: =IF(B21>0.85,"NGHI NGỜ — nhiều khả năng bạn quên một khoản chi phí","OK")
A25: → Giá bán nằm trong vùng neo? | B25: =IF(AND(B19>=B7,B19<=MAX(B13,B16)),"OK — trong vùng giá bán","XEM LẠI — ngoài vùng giá sàn/trần")
A27: BREAKEVEN CONTAINMENT — ngưỡng sống còn
A28: Ký hiệu: v = chi phí biến đổi / job thử · q = QA / job thử · e = chi phí 1 ca escalate
A29: v — chi phí biến đổi / job thử | B29: ='1_Cost_Job'!B31+'1_Cost_Job'!B38+'1_Cost_Job'!B43+'1_Cost_Job'!B47
A30: q — QA nội bộ / job thử | B30: ='1_Cost_Job'!B51*('1_Cost_Job'!B52/60)*'1_Cost_Job'!B50
A31: e — chi phí 1 ca escalate | B31: =IF('1_Cost_Job'!B6="B",('1_Cost_Job'!B53/60)*'1_Cost_Job'!B50,0)
A32: Gross Margin mục tiêu | B32: 0.6
A33: ★ Containment tối thiểu cần đạt | B33: =IF((B19*(1-B32)+B31)=0,0,(B29+B30+B31)/(B19*(1-B32)+B31)) | D33: Công thức: R ≥ (v+q+e) / (P×(1−GM)+e)
A34: Containment hiện tại (từ tab 1) | B34: ='1_Cost_Job'!B10
A35: → Kết luận | B35: =IF(B34>=B33,"ĐẠT — mô hình có lãi lành mạnh","CHƯA ĐẠT — phải tăng containment, tăng giá, hoặc đổi biến thể HITL")
A37: SENSITIVITY — mô hình gãy ở đâu?
A38: Containment | B38: Cost/Job | C38: Gross Margin | D38: Đánh giá
A39: 0.5 | B39: =($B$29+$B$30+$B$31*(1-A39))/A39 | C39: =IF($B$19=0,0,1-B39/$B$19) | D39: =IF(C39>=0.6,"An toàn",IF(C39>=0.5,"Cảnh báo","Nguy hiểm"))
A40: 0.6 | B40: =($B$29+$B$30+$B$31*(1-A40))/A40 | C40: =IF($B$19=0,0,1-B40/$B$19) | D40: =IF(C40>=0.6,"An toàn",IF(C40>=0.5,"Cảnh báo","Nguy hiểm"))
A41: 0.7 | B41: =($B$29+$B$30+$B$31*(1-A41))/A41 | C41: =IF($B$19=0,0,1-B41/$B$19) | D41: =IF(C41>=0.6,"An toàn",IF(C41>=0.5,"Cảnh báo","Nguy hiểm"))
A42: 0.8 | B42: =($B$29+$B$30+$B$31*(1-A42))/A42 | C42: =IF($B$19=0,0,1-B42/$B$19) | D42: =IF(C42>=0.6,"An toàn",IF(C42>=0.5,"Cảnh báo","Nguy hiểm"))
A43: 0.9 | B43: =($B$29+$B$30+$B$31*(1-A43))/A43 | C43: =IF($B$19=0,0,1-B43/$B$19) | D43: =IF(C43>=0.6,"An toàn",IF(C43>=0.5,"Cảnh báo","Nguy hiểm"))
A44: 0.95 | B44: =($B$29+$B$30+$B$31*(1-A44))/A44 | C44: =IF($B$19=0,0,1-B44/$B$19) | D44: =IF(C44>=0.6,"An toàn",IF(C44>=0.5,"Cảnh báo","Nguy hiểm"))
A46: Nhìn cột Gross Margin: mô hình của bạn mong manh đến mức nào khi AI làm sai nhiều hơn dự kiến?
...

Sheet 3_Value_Metric
A1: TAB 3 — VALUE METRIC SCORECARD
A2: Trạm 2. Chấm 0 / 1 / 2 điểm cho mỗi câu, theo THỰC TẾ HÔM NAY.
A4: A. ATTRIBUTION — bạn đo được kết quả là do AI tạo ra không?
A5: 1. Tôi có log đầy đủ mỗi job AI xử lý, gắn được với kết quả cuối cùng | B5: 0
A6: 2. Tôi có bộ eval đo được tỷ lệ AI làm đúng, có số liệu | B6: 0
A7: 3. Khách hàng đồng ý với cách tôi định nghĩa 'thành công' của một job | B7: 0
A8: 4. Tôi phân biệt được kết quả do AI tạo ra với kết quả do yếu tố khác | B8: 0
A9: 5. Tôi viết được định nghĩa chặt như Intercom: cái gì tính tiền, cái gì không | B9: 1
A10: → ĐIỂM ATTRIBUTION (tối đa 10) | B10: =SUM(B5:B9)
A12: B. AUTONOMY — AI tự chạy hay cần người?
A13: 1. AI hoàn thành job từ đầu đến cuối, không cần người bấm nút giữa chừng | B13: 0
A14: 2. Job chạy được ngoài giờ hành chính mà không ai trực | B14: 0
A15: 3. Khi AI không chắc, nó tự chuyển tiếp đúng chỗ — không cần người phân loại | B15: 0
A16: 4. Tỷ lệ ca phải có người can thiệp dưới 20% | B16: 0
A17: 5. Người vận hành chỉ kiểm tra mẫu (QA), không xử lý từng ca | B17: 0
A18: → ĐIỂM AUTONOMY (tối đa 10) | B18: =SUM(B13:B17)
A20: GỢI Ý CỦA MODEL
A21: → Value Metric gợi ý | B21: =IF(AND(B10>=7,B18>=7),"OUTCOME",IF(AND(B10>=7,B18<7),"USAGE",IF(AND(B10<7,B18>=7),"USAGE (an toàn)","SEAT hoặc HYBRID")))
A22: Ngưỡng 7/10 là quy ước của bài tập, không phải chuẩn ngành — dùng để buộc bạn ra quyết định, không phải để thay bạn quyết định.
A24: BENCHMARK NGƯỢC — 2 sản phẩm thật cùng loại job
A25: Tên sản phẩm | B25: Value Metric | C25: Giá công bố | D25: Link nguồn
A26: Swarmia Standard | B26: Seat | C26: $45/dev/tháng, annual billing | D26: https://www.swarmia.com/pricing/
A27: LinearB Essentials | B27: Hybrid: seat + AI credits | C27: $29/user/tháng annual; 1.000 credits; thêm từ $0,015/credit | D27: https://linearb.io/pricing
A29: QUYẾT ĐỊNH CUỐI
A30: Value Metric tôi chọn | B30: Hybrid
A31: Nếu KHÁC gợi ý — lý do thị trường là gì? | B31: Không override: khớp Seat/Hybrid. CTO vẫn review, chưa đủ bằng chứng bán Outcome.
A32: Decision Note — câu 1: tôi chọn đơn vị nào? | B32: Workspace fee cho kết nối + Usage/báo cáo AI-ready; từ báo cáo đầu, không báo cáo miễn phí.
A33: Decision Note — câu 2: bằng chứng Attribution / Autonomy? | B33: Attribution 1/10; Autonomy 0/10. Chưa có log/eval/pilot; rule viết được nhưng chưa validate.
A34: Decision Note — câu 3: mô hình này lỗ trong tình huống nào? | B34: Lỗ khi refresh vô hạn hoặc nhà cung cấp chịu sửa mọi ca; quota dataset, kỳ và opt-in overage.

Sheet 4_Channel_Fit
A1: TAB 4 — CHANNEL FIT & AFFORDABILITY TEST
A2: Trạm 4. Chọn ĐÚNG 1 kênh cho 90 ngày đầu — và chứng minh bằng số.
A4: A. NGÂN SÁCH CAC — bạn nuôi nổi kênh nào?
A5: ARPU / tháng ($) | B5: 219
A6: Gross Margin (từ tab 2_Pricing) | B6: ='2_Pricing'!B21
A7: Phân khúc (SMB / Mid / Enterprise) | B7: SMB
A8: → CAC payback cho phép (tháng) | B8: =IF(B7="SMB",12,IF(B7="Mid",18,24)) | C8: tháng | D8: Bessemer, Scaling to $100M (2024)
A9: ★ NGÂN SÁCH CAC / khách | B9: =B5*B6*B8 | D9: ARPU × GM × số tháng payback
A10: → ACV (giá trị hợp đồng / năm) | B10: =B5*12
A12: B. SALES VIABILITY — một AE phải chốt bao nhiêu deal?
A13: Quota / AE / năm ($) | B13: 120000 | D13: Giả định gốc của Tunguz (2016) — thay bằng số thị trường bạn
A14: Số ngày làm việc / năm | B14: 250 | C14: ngày
A15: → Số deal / AE / năm | B15: =IF(B10=0,0,B13/B10)
A16: ★ Số deal / AE / NGÀY | B16: =IF(B14=0,0,B15/B14) | C16: deal/ngày
A17: → Kết luận Sales-Led | B17: =IF(B16<=1,"KHẢ THI về mặt số học","BẤT KHẢ THI — ACV quá thấp để nuôi sales rep")
A19: C. ĐỐI CHIẾU CAC THỰC TẾ CỦA MOTION CÓ SALES
A20: Cost per opportunity ($) | B20: 1200 | D20: ICONIQ 2026 theo phân khúc: $6.300 · $8.000 · $11.200
A21: Win rate | B21: 0.25
A22: → CAC thực tế ước tính / khách | B22: =IF(B21=0,0,B20/B21)
A23: ★ Lệch bao nhiêu lần so với ngân sách CAC? | B23: =IF(B9=0,0,B22/B9) | D23: Đây là bằng chứng chọn kênh của bạn
A24: → Kết luận | B24: =IF(B23<=1,"Motion có sales KHẢ THI",IF(B23<=3,"Căng — cần tăng giá hoặc giảm chi phí bán hàng","KHÔNG KHẢ THI — đi PLG hoặc Partner-Led"))
A26: D. CHẤM ĐIỂM 3 KÊNH (1 = rất kém, 5 = rất tốt)
A27: Tiêu chí | B27: PLG | C27: Sales-Led | D27: Partner-Led
A28: 1. Ngân sách CAC của tôi nuôi nổi kênh này | B28: 4 | C28: 1 | D28: 2
A29: 2. Khách hàng mục tiêu thực sự mua theo cách này | B29: 3 | C29: 4 | D29: 2
A30: 3. Đội hiện tại có năng lực chạy kênh này ngay | B30: 3 | C30: 2 | D30: 1
A31: 4. Tôi tiếp cận được điểm nhúng / partner trong 30 ngày | B31: 3 | C31: 4 | D31: 1
A32: 5. Kênh này đưa tôi đến ĐÚNG Pain Moment | B32: 5 | C32: 3 | D32: 3
A33: 6. Tôi đo được hiệu quả trong vòng 90 ngày | B33: 4 | C33: 3 | D33: 2
A34: → TỔNG ĐIỂM | B34: =SUM(B28:B33) | C34: =SUM(C28:C33) | D34: =SUM(D28:D33)
A35: → Kênh điểm cao nhất | B35: =IF(AND(B34>=C34,B34>=D34),"PLG",IF(C34>=D34,"Sales-Led","Partner-Led"))
A37: E. CHỐT KÊNH
A38: ★ Kênh tôi chọn cho 90 ngày đầu | B38: PLG | D38: ĐÚNG 1 kênh. Chọn 2 kênh trở lên bị trừ điểm.
A39: Nếu Partner-Led: TÊN CÔNG TY partner | B39: Không áp dụng: GitHub, Inc. là bề mặt phân phối, chưa có partner hợp đồng. | D39: 'Các nền tảng trong ngành' = chưa có kênh
A40: Đã nói chuyện với họ chưa? (Rồi / Chưa) | B40: Chưa; không chọn Partner-Led
A41: Bạn mang lại giá trị gì cho partner? | B41: Không áp dụng. Khách tự cài GitHub App; không giả quan hệ partner hoặc commission.
A42: Nếu rơi vào vùng không khả thi — lối thoát nào? | B42: Giữ PLG tự phục vụ; thử 3 pilot nhỏ trong 30 ngày. Không tuyển AE khi CAC rep $4.800 vượt budget. | D42: Giảm giá để tự phục vụ / tăng giá + service / Partner-Led

Sheet 5_90Day_Plan
A1: TAB 5 — PAIN MOMENT · 90-DAY PLAN · EVIDENCE PACK
A2: Trạm 5 và Trạm 6.
A4: A. PAIN MOMENT — phải đủ 3 phần
A5: MẤY GIỜ khách đau nhất?
A6: Lúc đó họ ĐANG LÀM GÌ?
A7: Họ đang DÙNG APP / KÊNH NÀO?
A8: → Điểm nhúng cụ thể của bạn | D8: Một bề mặt tích hợp có tên, không phải 'website của chúng tôi'
A10: B. 90-DAY PLAN
B11: THÁNG 1 — Học | C11: THÁNG 2–3 — Đòn bẩy | D11: THÁNG 4+ — Mở rộng
A12: Kênh sử dụng
A13: Mục tiêu số khách
A14: Việc cụ thể 1
A15: Việc cụ thể 2
A16: Việc cụ thể 3
A17: KPI đo được
A18: Người chịu trách nhiệm
A19: Tháng 1 là giai đoạn HỌC, không phải scale. Kế hoạch 'tháng 1 lấy 200 khách ở 5 ngành' là kế hoạch chưa ai từng thử làm.
A21: C. EVIDENCE PACK — 3 tài sản bán hàng
A22: Tài sản | B22: Đã có? (Rồi/Chưa) | C22: Nội dung 1 câu — hoặc việc cần làm | D22: Người phụ trách · Deadline
A23: 1. Eval Results
A24: 2. Risk Checklist
A25: 3. Pilot Report
A26: Ô nào CHƯA CÓ thì ghi deadline — đừng bỏ trống. Thành thật về khoảng trống được điểm cao hơn bịa nội dung.
A28: D. BÀI TEST NGƯỜI LẠ — nhóm khác đọc One-Pager trong 2 phút
A29: Họ trả lời được: bán gì, cho ai, tính tiền theo đơn vị nào? (Được/Không)
A30: Họ trả lời được: có lãi trên mỗi đơn vị không, số nào chứng minh? (Được/Không)
A31: Họ trả lời được: tiếp cận khách qua đâu, vì sao kênh đó? (Được/Không)
A32: Số câu họ phải hỏi lại (mục tiêu ≤ 3)

Sheet 6_Benchmarks
A1: TAB 6 — BENCHMARKS (CHỈ ĐỌC)
A2: Giá chốt ngày 26/08/2026. Dòng có ⏳ là GIÁ KHUYẾN MẠI CÓ HẠN — phải kiểm tra lại.
A3: NGÀY BẠN KIỂM TRA LẠI GIÁ | B3: 2026-10-08 | D3: Bắt buộc điền — Rubric có chấm mục này
A5: Nhóm | B5: Mục | C5: Giá | D5: Đơn vị | E5: Nguồn
A6: LLM | B6: Claude Opus 5 — input / output | C6: 5,00 / 25,00 | D6: $ / 1M token | E6: platform.claude.com/docs/en/about-claude/pricing
A7: LLM | B7: Claude Sonnet 5 — input / output | C7: 2,00 / 10,00 | D7: $ / 1M token | E7: platform.claude.com/docs/en/about-claude/pricing
A8: LLM | B8: Claude Haiku 4.5 — input / output | C8: 1,00 / 5,00 | D8: $ / 1M token | E8: platform.claude.com/docs/en/about-claude/pricing
A9: LLM | B9: Claude — cache write 5' / cache read | C9: 1,25× / 0,10× input | D9: hệ số | E9: platform.claude.com/docs/en/about-claude/pricing
A10: LLM | B10: ⏳ OpenAI GPT-5.6 Sol — input / output | C10: 4,00 / 20,00 | D10: $ / 1M token | E10: developers.openai.com/api/docs/pricing (KM 21/08–21/11/2026; list 5,00/30,00)
A11: LLM | B11: OpenAI GPT-5.6 Luna — input / output | C11: 0,20 / 1,20 | D11: $ / 1M token | E11: developers.openai.com/api/docs/pricing
A12: LLM | B12: OpenAI — cached input / Batch API | C12: 10% input / −50% | D12: hệ số | E12: developers.openai.com/api/docs/pricing
A13: LLM | B13: Gemini 3.1 Pro — input / output (≤200k) | C13: 2,00 / 12,00 | D13: $ / 1M token | E13: ai.google.dev/gemini-api/docs/pricing
A14: LLM | B14: ⏳ Gemini 3.7 Flash — input / output | C14: 0,75 / 3,75 | D14: $ / 1M token | E14: ai.google.dev/gemini-api/docs/pricing (KM đến 31/12/2026; sau đó 1,50/7,50)
A15: STT | B15: Deepgram Nova-3 — pre-recorded | C15: 0,0043 | D15: $ / phút | E15: deepgram.com/pricing
A16: STT | B16: ⏳ Deepgram Nova-3 — streaming | C16: list 0,0077 · KM 0,0048 | D16: $ / phút | E16: deepgram.com/pricing — đang khuyến mại, kiểm tra lại
... A41: Benchmark | B41: ACV sàn cho inside sales | C41: ≈ 3.000 | D41: $ / năm | E41: Tomasz Tunguz (2016) — có kèm giả định để tính lại
A43: Lưu ý: trang marketing của nhà cung cấp có thể hiển thị giá cũ hơn trang docs. Ưu tiên trang docs / pricing chính thức.

Sheet 7_Assumptions
A1: DAY22 — DEVPULSE: ASSUMPTIONS & TRACEABILITY
A2: Giả định vận hành ≠ eval thực đo. Các tab gốc giữ nguyên giá trị ngoài ô vàng.
A3: Key | B3: Value | C3: Unit | D3: Evidence status | E3: Rationale / verification | F3: Source
A4: Product | B4: DevPulse AI | C4: text | D4: Day20 specification | E4: CTO engineering and AI-cost reporting | F4: data/day20-metrics-pack.md
A5: ICP minimum developers | B5: 20 | C5: developers | D5: hypothesis | E5: Narrow growth-team ICP; validate interviews | F5: Day20 segments
A6: ICP maximum developers | B6: 50 | C6: developers | D6: hypothesis | E6: Do not claim validated market | F6: Day20 segments
A7: Budget owner | B7: CTO; CEO/CFO per approval limit | C7: text | D7: hypothesis | E7: Pilot confirms actual signer | F7: docs/checkpoints/01-budget-job.md
A8: Budget line | B8: Engineering Operations / Reporting | C8: text | D8: hypothesis | E8: Time spent consolidating reporting | F8: docs/checkpoints/01-budget-job.md
A9: Positioning | B9: Chuẩn bị báo cáo Sprint/tháng có nguồn để CTO giải trình delivery và chi phí AI. | C9: text | D9: design | E9: Not causal ROI outcome | F9: Day20
A10: Workspace base fee | B10: 39 | C10: USD/workspace/month | D10: pricing hypothesis | E10: Connections, history, standard support; zero included reports | F10: Decision Note
A11: Reports/customer/month | B11: ='2_Pricing'!B11 | C11: reports | D11: planning | E11: 2 sprint + 1 board report; average delivered | F11: Day20 cadence
A12: Planning workspaces | B12: 10 | C12: workspaces | D12: hypothesis | E12: Target steady planning cohort, not current users | F12: 90-day plan
A13: Attempts/workspace/month | B13: ='1_Cost_Job'!B9/B12 | C13: attempts | D13: derived | E13: 40 attempts allocated to 10 workspaces | F13: 1_Cost_Job!B9
A14: Data coverage gate | B14: 0.8 | C14: fraction | D14: design | E14: Coverage of active developers; suppress report if missing ledger | F14: Day20 NSM
A15: Internal QA sample | B15: ='1_Cost_Job'!B51 | C15: fraction | D15: hypothesis | E15: 25% sample while early; customer final review every report | F15: 1_Cost_Job!B51
A16: Customer review minutes | B16: 30 | C16: minutes/report | D16: Day20 specification | E16: Not replaced by AI; cost borne by customer | F16: Day20 action effort 15–30min
A17: Net preparation hours saved/report | B17: 10 | C17: hours | D17: hypothesis | E17: Excludes final CTO review; stopwatch before/after | F17: Pilot Protocol
A18: Customer preparation labor | B18: 40 | C18: USD/hour | D18: hypothesis | E18: Fully loaded lead/analyst time; no wage benchmark claim | F18: Pilot interview required
A19: Monthly value anchor | B19: =B11*B17*B18 | C19: USD/month | D19: derived estimate | E19: No double-counting token or productivity savings | F19: 2_Pricing!B10
A20: Reporting role wage | B20: ='2_Pricing'!B14 | C20: USD/month | D20: hypothesis | E20: Secondary anchor only; no whole role replacement claim | F20: 2_Pricing!B14
A21: Monthly vendor COGS | B21: ='1_Cost_Job'!B62+'1_Cost_Job'!B63 | C21: USD/month | D21: derived | E21: All direct service costs | F21: 1_Cost_Job
A22: Monthly cohort revenue | B22: =B12*(B10+B11*'2_Pricing'!B19) | C22: USD/month | D22: derived forecast | E22: Base is additional, no included-report double charge | F22: Hybrid pricing
A23: Blended cohort GM | B23: =1-B21/B22 | C23: fraction | D23: derived forecast | E23: COGS includes workspace service; show separately from report GM | F23: B21:B22
A24: Fully loaded Cost/Job | B24: ='1_Cost_Job'!B67 | C24: USD/report | D24: derived | E24: Overhead not included in gross margin | F24: 1_Cost_Job!B67
A25: ARPU | B25: =B10+B11*'2_Pricing'!B19 | C25: USD/month | D25: derived forecast | E25: 39 base + 3×60 reports | F25: B10:B11
A26: Conservative channel GM | B26: ='2_Pricing'!B21 | C26: fraction | D26: derived | E26: Use report GM, lower than blended; conservative CAC cap | F26: 2_Pricing!B21
A27: CAC budget | B27: ='4_Channel_Fit'!B9 | C27: USD/customer | D27: derived | E27: SMB 12-month ceiling is lab convention, not proved retention | F27: 4_Channel_Fit!B9
A28: PLG acquisition spend | B28: 1200 | C28: USD/90days | D28: hypothesis | E28: $800 founder content (40h×$20) + $200 content tools + $200 placement | F28: No actual spend
A29: GitHub App installs | B29: 60 | C29: installs/90days | D29: target | E29: Qualified org installations, not pageviews | F29: No actual installs
A30: Activation rate | B30: 0.2 | C30: fraction | D30: hypothesis | E30: First AI-ready report within 14 days | F30: Pilot funnel
A31: Activation to paid | B31: 0.25 | C31: fraction | D31: hypothesis | E31: 3 paid from 12 activated | F31: Pilot funnel
A32: PLG paid customers | B32: =B29*B30*B31 | C32: customers | D32: derived target | E32: No sales rep or partner commission | F32: B29:B31
A33: PLG CAC | B33: =B28/B32 | C33: USD/customer | D33: derived estimate | E33: Includes founder time and free trial service allowance | F33: B28:B32
A34: PLG payback months | B34: =B33/('4_Channel_Fit'!B5*'4_Channel_Fit'!B6) | C34: months | D34: derived estimate | E34: Use conservative report GM | F34: 4_Channel_Fit!B5:B6
A35: PLG operating CAC stop threshold | B35: 400 | C35: USD/customer | D35: decision hypothesis | E35: Pause paid acquisition above $400 until conversion measured | F35: PLG plan
A36: Shared service monthly floor | B36: 80 | C36: USD/month | D36: hypothesis | E36: Hosting, auth and connectors minimum; requires invoice | F36: Infra estimate
A37: Infra variable/attempt | B37: 8 | C37: USD/attempt | D37: hypothesis | E37: $3 ingestion/DB + $1 storage/egress + $1 logging/eval + $1.5 support + $1.5 collection/reserve | F37: Infra estimate
A38: Vendor QA minutes | B38: ='1_Cost_Job'!B52 | C38: minutes | D38: hypothesis | E38: Early sample review of evidence links and numerical accuracy | F38: QA plan
A39: Vendor fully loaded hourly rate | B39: ='1_Cost_Job'!B50 | C39: USD/hour | D39: hypothesis | E39: Labor estimate including burden | F39: QA plan
A40: Rep motion total annual acquisition cost | B40: 48000 | C40: USD/year | D40: hypothesis | E40: $24k AE + $12k marketing + $12k tools/management; fully loaded, local scenario | F40: Not ICONIQ benchmark
...
